<robot name="brazo_simple">
  <link name="base_link"/>
  <link name="link1">
  <visual>
    <geometry>
      <box size="0.1 0.1 0.5"/>
    </geometry>
    <material name="blue">
      <color rgba="0 0 1 1"/>
    </material>
  </visual>
</link>
  <link name="link2">
  <visual>
    <geometry>
      <box size="0.1 0.1 0.5"/>
    </geometry>
    <material name="red">
      <color rgba="1 0 0 1"/>
    </material>
  </visual>
</link>

  <joint name="joint1" type="revolute">
    <parent link="base_link"/>
    <child link="link1"/>
    <origin xyz="0 0 0.1" rpy="0 0 0"/>
    <axis xyz="0 0 1"/>
    <limit lower="-1.57" upper="1.57" effort="10" velocity="1"/>
  </joint>

  <joint name="joint2" type="revolute">
    <parent link="link1"/>
    <child link="link2"/>
    <origin xyz="0 0 0.5" rpy="0 0 0"/>
    <axis xyz="0 0 1"/>
    <limit lower="-1.57" upper="1.57" effort="10" velocity="1"/>
  </joint>
</robot>
